2025-09-30 01:19:18 - MTL_MEASUREMENT - INFO - MEASURE OK run=1 W=409.84mm H=608.30mm A=192605.51mm2 Type=Asymmetrical  [S1(W=251.9,H=252.4,A=63653) | S2(W=68.1,H=602.0,A=41276) | S3(W=332.0,H=96.2,A=31079) | S4(W=79.3,H=247.9,A=18503) | S5(W=84.7,H=90.0,A=7902) | S6(W=84.1,H=90.5,A=6519)]
2025-09-30 01:19:18 - MTL_MEASUREMENT - INFO - [API] ingest ok -> {'id': 23, 'run_no': 1, 'source_filename': '', 'output_filename': 'MTL_000001.jpg', 'width_mm': 409.84, 'height_mm': 608.3, 'area_mm2': 192605.51, 'type_name': 'Asymmetrical', 'meta': {'S': [{'H_mm': 252.4, 'W_mm': 251.9, 'name': 'S1', 'A_mm2': 63653.0}, {'H_mm': 602.0, 'W_mm': 68.1, 'name': 'S2', 'A_mm2': 41276.0}, {'H_mm': 96.2, 'W_mm': 332.0, 'name': 'S3', 'A_mm2': 31079.0}, {'H_mm': 247.9, 'W_mm': 79.3, 'name': 'S4', 'A_mm2': 18503.0}, {'H_mm': 90.0, 'W_mm': 84.7, 'name': 'S5', 'A_mm2': 7902.0}, {'H_mm': 90.5, 'W_mm': 84.1, 'name': 'S6', 'A_mm2': 6519.0}]}}
2025-09-30 01:29:19 - MTL_MEASUREMENT - INFO - MEASURE OK run=2 W=409.84mm H=608.30mm A=192605.51mm2 Type=Asymmetrical  [S1(W=251.9,H=252.4,A=63653) | S2(W=68.1,H=602.0,A=41276) | S3(W=332.0,H=96.2,A=31079) | S4(W=79.3,H=247.9,A=18503) | S5(W=84.7,H=90.0,A=7902) | S6(W=84.1,H=90.5,A=6519)]
2025-09-30 01:29:19 - MTL_MEASUREMENT - INFO - [API] ingest ok -> {'id': 24, 'run_no': 2, 'source_filename': '', 'output_filename': 'MTL_000002.jpg', 'width_mm': 409.84, 'height_mm': 608.3, 'area_mm2': 192605.51, 'type_name': 'Asymmetrical', 'meta': {'S': [{'H_mm': 252.4, 'W_mm': 251.9, 'name': 'S1', 'A_mm2': 63653.0}, {'H_mm': 602.0, 'W_mm': 68.1, 'name': 'S2', 'A_mm2': 41276.0}, {'H_mm': 96.2, 'W_mm': 332.0, 'name': 'S3', 'A_mm2': 31079.0}, {'H_mm': 247.9, 'W_mm': 79.3, 'name': 'S4', 'A_mm2': 18503.0}, {'H_mm': 90.0, 'W_mm': 84.7, 'name': 'S5', 'A_mm2': 7902.0}, {'H_mm': 90.5, 'W_mm': 84.1, 'name': 'S6', 'A_mm2': 6519.0}]}}
2025-09-30 01:35:37 - MTL_MEASUREMENT - INFO - MEASURE OK run=3 W=409.84mm H=608.30mm A=192605.51mm2 Type=Asymmetrical  [S1(W=251.9,H=252.4,A=64338) | S2(W=68.1,H=602.0,A=41995) | S3(W=332.0,H=96.2,A=32631) | S4(W=79.3,H=247.9,A=20218) | S5(W=84.7,H=90.0,A=7906) | S6(W=84.1,H=90.5,A=7142)]
2025-09-30 01:35:37 - MTL_MEASUREMENT - INFO - [API] ingest ok -> {'id': 25, 'run_no': 3, 'source_filename': '', 'output_filename': 'MTL_000003.jpg', 'width_mm': 409.84, 'height_mm': 608.3, 'area_mm2': 192605.51, 'type_name': 'Asymmetrical', 'meta': {'S': [{'H_mm': 252.4, 'W_mm': 251.9, 'name': 'S1', 'A_mm2': 64338.0}, {'H_mm': 602.0, 'W_mm': 68.1, 'name': 'S2', 'A_mm2': 41995.0}, {'H_mm': 96.2, 'W_mm': 332.0, 'name': 'S3', 'A_mm2': 32631.0}, {'H_mm': 247.9, 'W_mm': 79.3, 'name': 'S4', 'A_mm2': 20218.0}, {'H_mm': 90.0, 'W_mm': 84.7, 'name': 'S5', 'A_mm2': 7906.0}, {'H_mm': 90.5, 'W_mm': 84.1, 'name': 'S6', 'A_mm2': 7142.0}]}}
2025-09-30 01:41:37 - MTL_MEASUREMENT - INFO - MEASURE OK run=4 W=419.98mm H=609.32mm A=247799.53mm2 Type=Symmetrical
2025-09-30 01:41:37 - MTL_MEASUREMENT - INFO - [API] ingest ok -> {'id': 26, 'run_no': 4, 'source_filename': '', 'output_filename': 'MTL_000004.jpg', 'width_mm': 419.98, 'height_mm': 609.32, 'area_mm2': 247799.53, 'type_name': 'Symmetrical', 'meta': {'S': []}}
2025-09-30 01:45:34 - MTL_MEASUREMENT - INFO - MEASURE OK run=5 W=409.84mm H=608.30mm A=192605.51mm2 Type=Asymmetrical  [S1(W=251.9,H=252.4,A=64338) | S2(W=68.1,H=602.0,A=41995) | S3(W=332.0,H=96.2,A=32631) | S4(W=79.3,H=247.9,A=20218) | S5(W=84.7,H=90.0,A=7906) | S6(W=84.1,H=90.5,A=7142)]
2025-09-30 01:45:34 - MTL_MEASUREMENT - INFO - [API] ingest ok -> {'id': 27, 'run_no': 5, 'source_filename': '', 'output_filename': 'MTL_000005.jpg', 'width_mm': 409.84, 'height_mm': 608.3, 'area_mm2': 192605.51, 'type_name': 'Asymmetrical', 'meta': {'S': [{'H_mm': 252.4, 'W_mm': 251.9, 'name': 'S1', 'A_mm2': 64338.0}, {'H_mm': 602.0, 'W_mm': 68.1, 'name': 'S2', 'A_mm2': 41995.0}, {'H_mm': 96.2, 'W_mm': 332.0, 'name': 'S3', 'A_mm2': 32631.0}, {'H_mm': 247.9, 'W_mm': 79.3, 'name': 'S4', 'A_mm2': 20218.0}, {'H_mm': 90.0, 'W_mm': 84.7, 'name': 'S5', 'A_mm2': 7906.0}, {'H_mm': 90.5, 'W_mm': 84.1, 'name': 'S6', 'A_mm2': 7142.0}]}}
2025-09-30 01:45:53 - MTL_MEASUREMENT - INFO - MEASURE OK run=6 W=409.84mm H=608.30mm A=192605.51mm2 Type=Asymmetrical  [S1(W=251.9,H=252.4,A=64338) | S2(W=68.1,H=602.0,A=41995) | S3(W=332.0,H=96.2,A=32631) | S4(W=79.3,H=247.9,A=20218) | S5(W=84.7,H=90.0,A=7906) | S6(W=84.1,H=90.5,A=7142)]
2025-09-30 01:45:53 - MTL_MEASUREMENT - INFO - [API] ingest ok -> {'id': 28, 'run_no': 6, 'source_filename': '', 'output_filename': 'MTL_000006.jpg', 'width_mm': 409.84, 'height_mm': 608.3, 'area_mm2': 192605.51, 'type_name': 'Asymmetrical', 'meta': {'S': [{'H_mm': 252.4, 'W_mm': 251.9, 'name': 'S1', 'A_mm2': 64338.0}, {'H_mm': 602.0, 'W_mm': 68.1, 'name': 'S2', 'A_mm2': 41995.0}, {'H_mm': 96.2, 'W_mm': 332.0, 'name': 'S3', 'A_mm2': 32631.0}, {'H_mm': 247.9, 'W_mm': 79.3, 'name': 'S4', 'A_mm2': 20218.0}, {'H_mm': 90.0, 'W_mm': 84.7, 'name': 'S5', 'A_mm2': 7906.0}, {'H_mm': 90.5, 'W_mm': 84.1, 'name': 'S6', 'A_mm2': 7142.0}]}}
2025-09-30 02:20:22 - MTL_MEASUREMENT - INFO - MEASURE OK run=1 W=409.84mm H=608.30mm A=192605.51mm2 Type=Asymmetrical  [S1(W=251.9,H=252.4,A=64338) | S2(W=68.1,H=602.0,A=41995) | S3(W=332.0,H=96.2,A=32631) | S4(W=79.3,H=247.9,A=20218) | S5(W=84.7,H=90.0,A=7906) | S6(W=84.1,H=90.5,A=7142)]
2025-09-30 02:20:22 - MTL_MEASUREMENT - ERROR - Send to API failed: HTTPConnectionPool(host='localhost', port=8000): Max retries exceeded with url: /measurements/ingest (Caused by NewConnectionError('<urllib3.connection.HTTPConnection object at 0xffff6a46b2b0>: Failed to establish a new connection: [Errno 111] Connection refused'))
Traceback (most recent call last):
  File "/usr/lib/python3/dist-packages/urllib3/connection.py", line 159, in _new_conn
    conn = connection.create_connection(
  File "/usr/lib/python3/dist-packages/urllib3/util/connection.py", line 84, in create_connection
    raise err
  File "/usr/lib/python3/dist-packages/urllib3/util/connection.py", line 74, in create_connection
    sock.connect(sa)
ConnectionRefusedError: [Errno 111] Connection refused

During handling of the above exception, another exception occurred:

Traceback (most recent call last):
  File "/usr/lib/python3/dist-packages/urllib3/connectionpool.py", line 666, in urlopen
    httplib_response = self._make_request(
  File "/usr/lib/python3/dist-packages/urllib3/connectionpool.py", line 388, in _make_request
    conn.request(method, url, **httplib_request_kw)
  File "/usr/lib/python3.8/http/client.py", line 1256, in request
    self._send_request(method, url, body, headers, encode_chunked)
  File "/usr/lib/python3.8/http/client.py", line 1302, in _send_request
    self.endheaders(body, encode_chunked=encode_chunked)
  File "/usr/lib/python3.8/http/client.py", line 1251, in endheaders
    self._send_output(message_body, encode_chunked=encode_chunked)
  File "/usr/lib/python3.8/http/client.py", line 1011, in _send_output
    self.send(msg)
  File "/usr/lib/python3.8/http/client.py", line 951, in send
    self.connect()
  File "/usr/lib/python3/dist-packages/urllib3/connection.py", line 187, in connect
    conn = self._new_conn()
  File "/usr/lib/python3/dist-packages/urllib3/connection.py", line 171, in _new_conn
    raise NewConnectionError(
urllib3.exceptions.NewConnectionError: <urllib3.connection.HTTPConnection object at 0xffff6a46b2b0>: Failed to establish a new connection: [Errno 111] Connection refused

During handling of the above exception, another exception occurred:

Traceback (most recent call last):
  File "/home/nvidia/.local/lib/python3.8/site-packages/requests/adapters.py", line 486, in send
    resp = conn.urlopen(
  File "/usr/lib/python3/dist-packages/urllib3/connectionpool.py", line 720, in urlopen
    retries = retries.increment(
  File "/usr/lib/python3/dist-packages/urllib3/util/retry.py", line 438, in increment
    raise MaxRetryError(_pool, url, error or ResponseError(cause))
urllib3.exceptions.MaxRetryError: HTTPConnectionPool(host='localhost', port=8000): Max retries exceeded with url: /measurements/ingest (Caused by NewConnectionError('<urllib3.connection.HTTPConnection object at 0xffff6a46b2b0>: Failed to establish a new connection: [Errno 111] Connection refused'))

During handling of the above exception, another exception occurred:

Traceback (most recent call last):
  File "mtl_ui.py", line 554, in _handle_measure
    api_json = post_result_to_api(
  File "mtl_ui.py", line 140, in post_result_to_api
    r = requests.post(url, data=data, files=files, timeout=timeout_s)
  File "/home/nvidia/.local/lib/python3.8/site-packages/requests/api.py", line 115, in post
    return request("post", url, data=data, json=json, **kwargs)
  File "/home/nvidia/.local/lib/python3.8/site-packages/requests/api.py", line 59, in request
    return session.request(method=method, url=url, **kwargs)
  File "/home/nvidia/.local/lib/python3.8/site-packages/requests/sessions.py", line 589, in request
    resp = self.send(prep, **send_kwargs)
  File "/home/nvidia/.local/lib/python3.8/site-packages/requests/sessions.py", line 703, in send
    r = adapter.send(request, **kwargs)
  File "/home/nvidia/.local/lib/python3.8/site-packages/requests/adapters.py", line 519, in send
    raise ConnectionError(e, request=request)
requests.exceptions.ConnectionError: HTTPConnectionPool(host='localhost', port=8000): Max retries exceeded with url: /measurements/ingest (Caused by NewConnectionError('<urllib3.connection.HTTPConnection object at 0xffff6a46b2b0>: Failed to establish a new connection: [Errno 111] Connection refused'))
2025-09-30 02:35:32 - MTL_MEASUREMENT - INFO - MEASURE OK run=2 W=409.84mm H=608.30mm A=192605.51mm2 Type=Asymmetrical  [S1(W=251.9,H=252.4,A=64338) | S2(W=68.1,H=602.0,A=41995) | S3(W=332.0,H=96.2,A=32631) | S4(W=79.3,H=247.9,A=20218) | S5(W=84.7,H=90.0,A=7906) | S6(W=84.1,H=90.5,A=7142)]
2025-09-30 02:35:32 - MTL_MEASUREMENT - ERROR - Send to API failed: HTTPConnectionPool(host='localhost', port=8000): Max retries exceeded with url: /measurements/ingest (Caused by NewConnectionError('<urllib3.connection.HTTPConnection object at 0xffff60d4e2b0>: Failed to establish a new connection: [Errno 111] Connection refused'))
Traceback (most recent call last):
  File "/usr/lib/python3/dist-packages/urllib3/connection.py", line 159, in _new_conn
    conn = connection.create_connection(
  File "/usr/lib/python3/dist-packages/urllib3/util/connection.py", line 84, in create_connection
    raise err
  File "/usr/lib/python3/dist-packages/urllib3/util/connection.py", line 74, in create_connection
    sock.connect(sa)
ConnectionRefusedError: [Errno 111] Connection refused

During handling of the above exception, another exception occurred:

Traceback (most recent call last):
  File "/usr/lib/python3/dist-packages/urllib3/connectionpool.py", line 666, in urlopen
    httplib_response = self._make_request(
  File "/usr/lib/python3/dist-packages/urllib3/connectionpool.py", line 388, in _make_request
    conn.request(method, url, **httplib_request_kw)
  File "/usr/lib/python3.8/http/client.py", line 1256, in request
    self._send_request(method, url, body, headers, encode_chunked)
  File "/usr/lib/python3.8/http/client.py", line 1302, in _send_request
    self.endheaders(body, encode_chunked=encode_chunked)
  File "/usr/lib/python3.8/http/client.py", line 1251, in endheaders
    self._send_output(message_body, encode_chunked=encode_chunked)
  File "/usr/lib/python3.8/http/client.py", line 1011, in _send_output
    self.send(msg)
  File "/usr/lib/python3.8/http/client.py", line 951, in send
    self.connect()
  File "/usr/lib/python3/dist-packages/urllib3/connection.py", line 187, in connect
    conn = self._new_conn()
  File "/usr/lib/python3/dist-packages/urllib3/connection.py", line 171, in _new_conn
    raise NewConnectionError(
urllib3.exceptions.NewConnectionError: <urllib3.connection.HTTPConnection object at 0xffff60d4e2b0>: Failed to establish a new connection: [Errno 111] Connection refused

During handling of the above exception, another exception occurred:

Traceback (most recent call last):
  File "/home/nvidia/.local/lib/python3.8/site-packages/requests/adapters.py", line 486, in send
    resp = conn.urlopen(
  File "/usr/lib/python3/dist-packages/urllib3/connectionpool.py", line 720, in urlopen
    retries = retries.increment(
  File "/usr/lib/python3/dist-packages/urllib3/util/retry.py", line 438, in increment
    raise MaxRetryError(_pool, url, error or ResponseError(cause))
urllib3.exceptions.MaxRetryError: HTTPConnectionPool(host='localhost', port=8000): Max retries exceeded with url: /measurements/ingest (Caused by NewConnectionError('<urllib3.connection.HTTPConnection object at 0xffff60d4e2b0>: Failed to establish a new connection: [Errno 111] Connection refused'))

During handling of the above exception, another exception occurred:

Traceback (most recent call last):
  File "mtl_ui.py", line 554, in _handle_measure
    api_json = post_result_to_api(
  File "mtl_ui.py", line 140, in post_result_to_api
    r = requests.post(url, data=data, files=files, timeout=timeout_s)
  File "/home/nvidia/.local/lib/python3.8/site-packages/requests/api.py", line 115, in post
    return request("post", url, data=data, json=json, **kwargs)
  File "/home/nvidia/.local/lib/python3.8/site-packages/requests/api.py", line 59, in request
    return session.request(method=method, url=url, **kwargs)
  File "/home/nvidia/.local/lib/python3.8/site-packages/requests/sessions.py", line 589, in request
    resp = self.send(prep, **send_kwargs)
  File "/home/nvidia/.local/lib/python3.8/site-packages/requests/sessions.py", line 703, in send
    r = adapter.send(request, **kwargs)
  File "/home/nvidia/.local/lib/python3.8/site-packages/requests/adapters.py", line 519, in send
    raise ConnectionError(e, request=request)
requests.exceptions.ConnectionError: HTTPConnectionPool(host='localhost', port=8000): Max retries exceeded with url: /measurements/ingest (Caused by NewConnectionError('<urllib3.connection.HTTPConnection object at 0xffff60d4e2b0>: Failed to establish a new connection: [Errno 111] Connection refused'))
2025-09-30 02:41:19 - MTL_MEASUREMENT - INFO - MEASURE OK run=3 W=409.84mm H=608.30mm A=192605.51mm2 Type=Asymmetrical  [S1(W=251.9,H=252.4,A=64338) | S2(W=68.1,H=602.0,A=41995) | S3(W=332.0,H=96.2,A=32631) | S4(W=79.3,H=247.9,A=20218) | S5(W=84.7,H=90.0,A=7906) | S6(W=84.1,H=90.5,A=7142)]
2025-09-30 02:41:19 - MTL_MEASUREMENT - ERROR - Send to API failed: HTTPConnectionPool(host='localhost', port=8000): Max retries exceeded with url: /measurements/ingest (Caused by NewConnectionError('<urllib3.connection.HTTPConnection object at 0xffff64825fa0>: Failed to establish a new connection: [Errno 111] Connection refused'))
Traceback (most recent call last):
  File "/usr/lib/python3/dist-packages/urllib3/connection.py", line 159, in _new_conn
    conn = connection.create_connection(
  File "/usr/lib/python3/dist-packages/urllib3/util/connection.py", line 84, in create_connection
    raise err
  File "/usr/lib/python3/dist-packages/urllib3/util/connection.py", line 74, in create_connection
    sock.connect(sa)
ConnectionRefusedError: [Errno 111] Connection refused

During handling of the above exception, another exception occurred:

Traceback (most recent call last):
  File "/usr/lib/python3/dist-packages/urllib3/connectionpool.py", line 666, in urlopen
    httplib_response = self._make_request(
  File "/usr/lib/python3/dist-packages/urllib3/connectionpool.py", line 388, in _make_request
    conn.request(method, url, **httplib_request_kw)
  File "/usr/lib/python3.8/http/client.py", line 1256, in request
    self._send_request(method, url, body, headers, encode_chunked)
  File "/usr/lib/python3.8/http/client.py", line 1302, in _send_request
    self.endheaders(body, encode_chunked=encode_chunked)
  File "/usr/lib/python3.8/http/client.py", line 1251, in endheaders
    self._send_output(message_body, encode_chunked=encode_chunked)
  File "/usr/lib/python3.8/http/client.py", line 1011, in _send_output
    self.send(msg)
  File "/usr/lib/python3.8/http/client.py", line 951, in send
    self.connect()
  File "/usr/lib/python3/dist-packages/urllib3/connection.py", line 187, in connect
    conn = self._new_conn()
  File "/usr/lib/python3/dist-packages/urllib3/connection.py", line 171, in _new_conn
    raise NewConnectionError(
urllib3.exceptions.NewConnectionError: <urllib3.connection.HTTPConnection object at 0xffff64825fa0>: Failed to establish a new connection: [Errno 111] Connection refused

During handling of the above exception, another exception occurred:

Traceback (most recent call last):
  File "/home/nvidia/.local/lib/python3.8/site-packages/requests/adapters.py", line 486, in send
    resp = conn.urlopen(
  File "/usr/lib/python3/dist-packages/urllib3/connectionpool.py", line 720, in urlopen
    retries = retries.increment(
  File "/usr/lib/python3/dist-packages/urllib3/util/retry.py", line 438, in increment
    raise MaxRetryError(_pool, url, error or ResponseError(cause))
urllib3.exceptions.MaxRetryError: HTTPConnectionPool(host='localhost', port=8000): Max retries exceeded with url: /measurements/ingest (Caused by NewConnectionError('<urllib3.connection.HTTPConnection object at 0xffff64825fa0>: Failed to establish a new connection: [Errno 111] Connection refused'))

During handling of the above exception, another exception occurred:

Traceback (most recent call last):
  File "mtl_ui.py", line 554, in _handle_measure
    api_json = post_result_to_api(
  File "mtl_ui.py", line 140, in post_result_to_api
    r = requests.post(url, data=data, files=files, timeout=timeout_s)
  File "/home/nvidia/.local/lib/python3.8/site-packages/requests/api.py", line 115, in post
    return request("post", url, data=data, json=json, **kwargs)
  File "/home/nvidia/.local/lib/python3.8/site-packages/requests/api.py", line 59, in request
    return session.request(method=method, url=url, **kwargs)
  File "/home/nvidia/.local/lib/python3.8/site-packages/requests/sessions.py", line 589, in request
    resp = self.send(prep, **send_kwargs)
  File "/home/nvidia/.local/lib/python3.8/site-packages/requests/sessions.py", line 703, in send
    r = adapter.send(request, **kwargs)
  File "/home/nvidia/.local/lib/python3.8/site-packages/requests/adapters.py", line 519, in send
    raise ConnectionError(e, request=request)
requests.exceptions.ConnectionError: HTTPConnectionPool(host='localhost', port=8000): Max retries exceeded with url: /measurements/ingest (Caused by NewConnectionError('<urllib3.connection.HTTPConnection object at 0xffff64825fa0>: Failed to establish a new connection: [Errno 111] Connection refused'))
2025-09-30 02:42:00 - MTL_MEASUREMENT - WARNING - MEASURE NO_OBJECT
2025-09-30 02:52:32 - MTL_MEASUREMENT - WARNING - MEASURE NO_OBJECT
2025-09-30 02:53:24 - MTL_MEASUREMENT - INFO - MEASURE OK run=4 W=409.13mm H=608.30mm A=99291.65mm2 Type=Asymmetrical  [S1(W=101.5,H=602.1,A=62552) | S2(W=301.2,H=114.7,A=35259)]
2025-09-30 02:53:24 - MTL_MEASUREMENT - ERROR - Send to API failed: HTTPConnectionPool(host='localhost', port=8000): Max retries exceeded with url: /measurements/ingest (Caused by NewConnectionError('<urllib3.connection.HTTPConnection object at 0xffff5abeffd0>: Failed to establish a new connection: [Errno 111] Connection refused'))
Traceback (most recent call last):
  File "/usr/lib/python3/dist-packages/urllib3/connection.py", line 159, in _new_conn
    conn = connection.create_connection(
  File "/usr/lib/python3/dist-packages/urllib3/util/connection.py", line 84, in create_connection
    raise err
  File "/usr/lib/python3/dist-packages/urllib3/util/connection.py", line 74, in create_connection
    sock.connect(sa)
ConnectionRefusedError: [Errno 111] Connection refused

During handling of the above exception, another exception occurred:

Traceback (most recent call last):
  File "/usr/lib/python3/dist-packages/urllib3/connectionpool.py", line 666, in urlopen
    httplib_response = self._make_request(
  File "/usr/lib/python3/dist-packages/urllib3/connectionpool.py", line 388, in _make_request
    conn.request(method, url, **httplib_request_kw)
  File "/usr/lib/python3.8/http/client.py", line 1256, in request
    self._send_request(method, url, body, headers, encode_chunked)
  File "/usr/lib/python3.8/http/client.py", line 1302, in _send_request
    self.endheaders(body, encode_chunked=encode_chunked)
  File "/usr/lib/python3.8/http/client.py", line 1251, in endheaders
    self._send_output(message_body, encode_chunked=encode_chunked)
  File "/usr/lib/python3.8/http/client.py", line 1011, in _send_output
    self.send(msg)
  File "/usr/lib/python3.8/http/client.py", line 951, in send
    self.connect()
  File "/usr/lib/python3/dist-packages/urllib3/connection.py", line 187, in connect
    conn = self._new_conn()
  File "/usr/lib/python3/dist-packages/urllib3/connection.py", line 171, in _new_conn
    raise NewConnectionError(
urllib3.exceptions.NewConnectionError: <urllib3.connection.HTTPConnection object at 0xffff5abeffd0>: Failed to establish a new connection: [Errno 111] Connection refused

During handling of the above exception, another exception occurred:

Traceback (most recent call last):
  File "/home/nvidia/.local/lib/python3.8/site-packages/requests/adapters.py", line 486, in send
    resp = conn.urlopen(
  File "/usr/lib/python3/dist-packages/urllib3/connectionpool.py", line 720, in urlopen
    retries = retries.increment(
  File "/usr/lib/python3/dist-packages/urllib3/util/retry.py", line 438, in increment
    raise MaxRetryError(_pool, url, error or ResponseError(cause))
urllib3.exceptions.MaxRetryError: HTTPConnectionPool(host='localhost', port=8000): Max retries exceeded with url: /measurements/ingest (Caused by NewConnectionError('<urllib3.connection.HTTPConnection object at 0xffff5abeffd0>: Failed to establish a new connection: [Errno 111] Connection refused'))

During handling of the above exception, another exception occurred:

Traceback (most recent call last):
  File "mtl_ui.py", line 554, in _handle_measure
    api_json = post_result_to_api(
  File "mtl_ui.py", line 140, in post_result_to_api
    r = requests.post(url, data=data, files=files, timeout=timeout_s)
  File "/home/nvidia/.local/lib/python3.8/site-packages/requests/api.py", line 115, in post
    return request("post", url, data=data, json=json, **kwargs)
  File "/home/nvidia/.local/lib/python3.8/site-packages/requests/api.py", line 59, in request
    return session.request(method=method, url=url, **kwargs)
  File "/home/nvidia/.local/lib/python3.8/site-packages/requests/sessions.py", line 589, in request
    resp = self.send(prep, **send_kwargs)
  File "/home/nvidia/.local/lib/python3.8/site-packages/requests/sessions.py", line 703, in send
    r = adapter.send(request, **kwargs)
  File "/home/nvidia/.local/lib/python3.8/site-packages/requests/adapters.py", line 519, in send
    raise ConnectionError(e, request=request)
requests.exceptions.ConnectionError: HTTPConnectionPool(host='localhost', port=8000): Max retries exceeded with url: /measurements/ingest (Caused by NewConnectionError('<urllib3.connection.HTTPConnection object at 0xffff5abeffd0>: Failed to establish a new connection: [Errno 111] Connection refused'))
2025-09-30 02:53:58 - MTL_MEASUREMENT - INFO - MEASURE OK run=5 W=409.13mm H=608.30mm A=99291.65mm2 Type=Asymmetrical  [S1(W=101.5,H=602.1,A=62552) | S2(W=301.2,H=114.7,A=35259)]
2025-09-30 02:53:58 - MTL_MEASUREMENT - ERROR - Send to API failed: HTTPConnectionPool(host='localhost', port=8000): Max retries exceeded with url: /measurements/ingest (Caused by NewConnectionError('<urllib3.connection.HTTPConnection object at 0xffff5abeff40>: Failed to establish a new connection: [Errno 111] Connection refused'))
Traceback (most recent call last):
  File "/usr/lib/python3/dist-packages/urllib3/connection.py", line 159, in _new_conn
    conn = connection.create_connection(
  File "/usr/lib/python3/dist-packages/urllib3/util/connection.py", line 84, in create_connection
    raise err
  File "/usr/lib/python3/dist-packages/urllib3/util/connection.py", line 74, in create_connection
    sock.connect(sa)
ConnectionRefusedError: [Errno 111] Connection refused

During handling of the above exception, another exception occurred:

Traceback (most recent call last):
  File "/usr/lib/python3/dist-packages/urllib3/connectionpool.py", line 666, in urlopen
    httplib_response = self._make_request(
  File "/usr/lib/python3/dist-packages/urllib3/connectionpool.py", line 388, in _make_request
    conn.request(method, url, **httplib_request_kw)
  File "/usr/lib/python3.8/http/client.py", line 1256, in request
    self._send_request(method, url, body, headers, encode_chunked)
  File "/usr/lib/python3.8/http/client.py", line 1302, in _send_request
    self.endheaders(body, encode_chunked=encode_chunked)
  File "/usr/lib/python3.8/http/client.py", line 1251, in endheaders
    self._send_output(message_body, encode_chunked=encode_chunked)
  File "/usr/lib/python3.8/http/client.py", line 1011, in _send_output
    self.send(msg)
  File "/usr/lib/python3.8/http/client.py", line 951, in send
    self.connect()
  File "/usr/lib/python3/dist-packages/urllib3/connection.py", line 187, in connect
    conn = self._new_conn()
  File "/usr/lib/python3/dist-packages/urllib3/connection.py", line 171, in _new_conn
    raise NewConnectionError(
urllib3.exceptions.NewConnectionError: <urllib3.connection.HTTPConnection object at 0xffff5abeff40>: Failed to establish a new connection: [Errno 111] Connection refused

During handling of the above exception, another exception occurred:

Traceback (most recent call last):
  File "/home/nvidia/.local/lib/python3.8/site-packages/requests/adapters.py", line 486, in send
    resp = conn.urlopen(
  File "/usr/lib/python3/dist-packages/urllib3/connectionpool.py", line 720, in urlopen
    retries = retries.increment(
  File "/usr/lib/python3/dist-packages/urllib3/util/retry.py", line 438, in increment
    raise MaxRetryError(_pool, url, error or ResponseError(cause))
urllib3.exceptions.MaxRetryError: HTTPConnectionPool(host='localhost', port=8000): Max retries exceeded with url: /measurements/ingest (Caused by NewConnectionError('<urllib3.connection.HTTPConnection object at 0xffff5abeff40>: Failed to establish a new connection: [Errno 111] Connection refused'))

During handling of the above exception, another exception occurred:

Traceback (most recent call last):
  File "mtl_ui.py", line 554, in _handle_measure
    api_json = post_result_to_api(
  File "mtl_ui.py", line 140, in post_result_to_api
    r = requests.post(url, data=data, files=files, timeout=timeout_s)
  File "/home/nvidia/.local/lib/python3.8/site-packages/requests/api.py", line 115, in post
    return request("post", url, data=data, json=json, **kwargs)
  File "/home/nvidia/.local/lib/python3.8/site-packages/requests/api.py", line 59, in request
    return session.request(method=method, url=url, **kwargs)
  File "/home/nvidia/.local/lib/python3.8/site-packages/requests/sessions.py", line 589, in request
    resp = self.send(prep, **send_kwargs)
  File "/home/nvidia/.local/lib/python3.8/site-packages/requests/sessions.py", line 703, in send
    r = adapter.send(request, **kwargs)
  File "/home/nvidia/.local/lib/python3.8/site-packages/requests/adapters.py", line 519, in send
    raise ConnectionError(e, request=request)
requests.exceptions.ConnectionError: HTTPConnectionPool(host='localhost', port=8000): Max retries exceeded with url: /measurements/ingest (Caused by NewConnectionError('<urllib3.connection.HTTPConnection object at 0xffff5abeff40>: Failed to establish a new connection: [Errno 111] Connection refused'))
2025-09-30 02:54:53 - MTL_MEASUREMENT - INFO - MEASURE OK run=6 W=409.13mm H=608.30mm A=99291.65mm2 Type=Asymmetrical  [S1(W=101.5,H=602.1,A=62552) | S2(W=301.2,H=114.7,A=35259)]
2025-09-30 02:54:53 - MTL_MEASUREMENT - ERROR - Send to API failed: HTTPConnectionPool(host='localhost', port=8000): Max retries exceeded with url: /measurements/ingest (Caused by NewConnectionError('<urllib3.connection.HTTPConnection object at 0xffff7009bfd0>: Failed to establish a new connection: [Errno 111] Connection refused'))
Traceback (most recent call last):
  File "/usr/lib/python3/dist-packages/urllib3/connection.py", line 159, in _new_conn
    conn = connection.create_connection(
  File "/usr/lib/python3/dist-packages/urllib3/util/connection.py", line 84, in create_connection
    raise err
  File "/usr/lib/python3/dist-packages/urllib3/util/connection.py", line 74, in create_connection
    sock.connect(sa)
ConnectionRefusedError: [Errno 111] Connection refused

During handling of the above exception, another exception occurred:

Traceback (most recent call last):
  File "/usr/lib/python3/dist-packages/urllib3/connectionpool.py", line 666, in urlopen
    httplib_response = self._make_request(
  File "/usr/lib/python3/dist-packages/urllib3/connectionpool.py", line 388, in _make_request
    conn.request(method, url, **httplib_request_kw)
  File "/usr/lib/python3.8/http/client.py", line 1256, in request
    self._send_request(method, url, body, headers, encode_chunked)
  File "/usr/lib/python3.8/http/client.py", line 1302, in _send_request
    self.endheaders(body, encode_chunked=encode_chunked)
  File "/usr/lib/python3.8/http/client.py", line 1251, in endheaders
    self._send_output(message_body, encode_chunked=encode_chunked)
  File "/usr/lib/python3.8/http/client.py", line 1011, in _send_output
    self.send(msg)
  File "/usr/lib/python3.8/http/client.py", line 951, in send
    self.connect()
  File "/usr/lib/python3/dist-packages/urllib3/connection.py", line 187, in connect
    conn = self._new_conn()
  File "/usr/lib/python3/dist-packages/urllib3/connection.py", line 171, in _new_conn
    raise NewConnectionError(
urllib3.exceptions.NewConnectionError: <urllib3.connection.HTTPConnection object at 0xffff7009bfd0>: Failed to establish a new connection: [Errno 111] Connection refused

During handling of the above exception, another exception occurred:

Traceback (most recent call last):
  File "/home/nvidia/.local/lib/python3.8/site-packages/requests/adapters.py", line 486, in send
    resp = conn.urlopen(
  File "/usr/lib/python3/dist-packages/urllib3/connectionpool.py", line 720, in urlopen
    retries = retries.increment(
  File "/usr/lib/python3/dist-packages/urllib3/util/retry.py", line 438, in increment
    raise MaxRetryError(_pool, url, error or ResponseError(cause))
urllib3.exceptions.MaxRetryError: HTTPConnectionPool(host='localhost', port=8000): Max retries exceeded with url: /measurements/ingest (Caused by NewConnectionError('<urllib3.connection.HTTPConnection object at 0xffff7009bfd0>: Failed to establish a new connection: [Errno 111] Connection refused'))

During handling of the above exception, another exception occurred:

Traceback (most recent call last):
  File "mtl_ui.py", line 554, in _handle_measure
    api_json = post_result_to_api(
  File "mtl_ui.py", line 140, in post_result_to_api
    r = requests.post(url, data=data, files=files, timeout=timeout_s)
  File "/home/nvidia/.local/lib/python3.8/site-packages/requests/api.py", line 115, in post
    return request("post", url, data=data, json=json, **kwargs)
  File "/home/nvidia/.local/lib/python3.8/site-packages/requests/api.py", line 59, in request
    return session.request(method=method, url=url, **kwargs)
  File "/home/nvidia/.local/lib/python3.8/site-packages/requests/sessions.py", line 589, in request
    resp = self.send(prep, **send_kwargs)
  File "/home/nvidia/.local/lib/python3.8/site-packages/requests/sessions.py", line 703, in send
    r = adapter.send(request, **kwargs)
  File "/home/nvidia/.local/lib/python3.8/site-packages/requests/adapters.py", line 519, in send
    raise ConnectionError(e, request=request)
requests.exceptions.ConnectionError: HTTPConnectionPool(host='localhost', port=8000): Max retries exceeded with url: /measurements/ingest (Caused by NewConnectionError('<urllib3.connection.HTTPConnection object at 0xffff7009bfd0>: Failed to establish a new connection: [Errno 111] Connection refused'))
2025-09-30 02:55:20 - MTL_MEASUREMENT - INFO - MEASURE OK run=7 W=409.13mm H=608.30mm A=99291.65mm2 Type=Asymmetrical  [S1(W=101.5,H=602.1,A=62552) | S2(W=301.2,H=114.7,A=35259)]
2025-09-30 02:55:20 - MTL_MEASUREMENT - ERROR - Send to API failed: HTTPConnectionPool(host='localhost', port=8000): Max retries exceeded with url: /measurements/ingest (Caused by NewConnectionError('<urllib3.connection.HTTPConnection object at 0xffff7009bf40>: Failed to establish a new connection: [Errno 111] Connection refused'))
Traceback (most recent call last):
  File "/usr/lib/python3/dist-packages/urllib3/connection.py", line 159, in _new_conn
    conn = connection.create_connection(
  File "/usr/lib/python3/dist-packages/urllib3/util/connection.py", line 84, in create_connection
    raise err
  File "/usr/lib/python3/dist-packages/urllib3/util/connection.py", line 74, in create_connection
    sock.connect(sa)
ConnectionRefusedError: [Errno 111] Connection refused

During handling of the above exception, another exception occurred:

Traceback (most recent call last):
  File "/usr/lib/python3/dist-packages/urllib3/connectionpool.py", line 666, in urlopen
    httplib_response = self._make_request(
  File "/usr/lib/python3/dist-packages/urllib3/connectionpool.py", line 388, in _make_request
    conn.request(method, url, **httplib_request_kw)
  File "/usr/lib/python3.8/http/client.py", line 1256, in request
    self._send_request(method, url, body, headers, encode_chunked)
  File "/usr/lib/python3.8/http/client.py", line 1302, in _send_request
    self.endheaders(body, encode_chunked=encode_chunked)
  File "/usr/lib/python3.8/http/client.py", line 1251, in endheaders
    self._send_output(message_body, encode_chunked=encode_chunked)
  File "/usr/lib/python3.8/http/client.py", line 1011, in _send_output
    self.send(msg)
  File "/usr/lib/python3.8/http/client.py", line 951, in send
    self.connect()
  File "/usr/lib/python3/dist-packages/urllib3/connection.py", line 187, in connect
    conn = self._new_conn()
  File "/usr/lib/python3/dist-packages/urllib3/connection.py", line 171, in _new_conn
    raise NewConnectionError(
urllib3.exceptions.NewConnectionError: <urllib3.connection.HTTPConnection object at 0xffff7009bf40>: Failed to establish a new connection: [Errno 111] Connection refused

During handling of the above exception, another exception occurred:

Traceback (most recent call last):
  File "/home/nvidia/.local/lib/python3.8/site-packages/requests/adapters.py", line 486, in send
    resp = conn.urlopen(
  File "/usr/lib/python3/dist-packages/urllib3/connectionpool.py", line 720, in urlopen
    retries = retries.increment(
  File "/usr/lib/python3/dist-packages/urllib3/util/retry.py", line 438, in increment
    raise MaxRetryError(_pool, url, error or ResponseError(cause))
urllib3.exceptions.MaxRetryError: HTTPConnectionPool(host='localhost', port=8000): Max retries exceeded with url: /measurements/ingest (Caused by NewConnectionError('<urllib3.connection.HTTPConnection object at 0xffff7009bf40>: Failed to establish a new connection: [Errno 111] Connection refused'))

During handling of the above exception, another exception occurred:

Traceback (most recent call last):
  File "mtl_ui.py", line 554, in _handle_measure
    api_json = post_result_to_api(
  File "mtl_ui.py", line 140, in post_result_to_api
    r = requests.post(url, data=data, files=files, timeout=timeout_s)
  File "/home/nvidia/.local/lib/python3.8/site-packages/requests/api.py", line 115, in post
    return request("post", url, data=data, json=json, **kwargs)
  File "/home/nvidia/.local/lib/python3.8/site-packages/requests/api.py", line 59, in request
    return session.request(method=method, url=url, **kwargs)
  File "/home/nvidia/.local/lib/python3.8/site-packages/requests/sessions.py", line 589, in request
    resp = self.send(prep, **send_kwargs)
  File "/home/nvidia/.local/lib/python3.8/site-packages/requests/sessions.py", line 703, in send
    r = adapter.send(request, **kwargs)
  File "/home/nvidia/.local/lib/python3.8/site-packages/requests/adapters.py", line 519, in send
    raise ConnectionError(e, request=request)
requests.exceptions.ConnectionError: HTTPConnectionPool(host='localhost', port=8000): Max retries exceeded with url: /measurements/ingest (Caused by NewConnectionError('<urllib3.connection.HTTPConnection object at 0xffff7009bf40>: Failed to establish a new connection: [Errno 111] Connection refused'))
2025-09-30 02:56:13 - MTL_MEASUREMENT - INFO - MEASURE OK run=8 W=409.13mm H=608.30mm A=99291.65mm2 Type=Asymmetrical  [S1(W=101.5,H=602.1,A=62552) | S2(W=301.2,H=114.7,A=35259)]
2025-09-30 02:56:13 - MTL_MEASUREMENT - ERROR - Send to API failed: HTTPConnectionPool(host='localhost', port=8000): Max retries exceeded with url: /measurements/ingest (Caused by NewConnectionError('<urllib3.connection.HTTPConnection object at 0xffff659fdfd0>: Failed to establish a new connection: [Errno 111] Connection refused'))
Traceback (most recent call last):
  File "/usr/lib/python3/dist-packages/urllib3/connection.py", line 159, in _new_conn
    conn = connection.create_connection(
  File "/usr/lib/python3/dist-packages/urllib3/util/connection.py", line 84, in create_connection
    raise err
  File "/usr/lib/python3/dist-packages/urllib3/util/connection.py", line 74, in create_connection
    sock.connect(sa)
ConnectionRefusedError: [Errno 111] Connection refused

During handling of the above exception, another exception occurred:

Traceback (most recent call last):
  File "/usr/lib/python3/dist-packages/urllib3/connectionpool.py", line 666, in urlopen
    httplib_response = self._make_request(
  File "/usr/lib/python3/dist-packages/urllib3/connectionpool.py", line 388, in _make_request
    conn.request(method, url, **httplib_request_kw)
  File "/usr/lib/python3.8/http/client.py", line 1256, in request
    self._send_request(method, url, body, headers, encode_chunked)
  File "/usr/lib/python3.8/http/client.py", line 1302, in _send_request
    self.endheaders(body, encode_chunked=encode_chunked)
  File "/usr/lib/python3.8/http/client.py", line 1251, in endheaders
    self._send_output(message_body, encode_chunked=encode_chunked)
  File "/usr/lib/python3.8/http/client.py", line 1011, in _send_output
    self.send(msg)
  File "/usr/lib/python3.8/http/client.py", line 951, in send
    self.connect()
  File "/usr/lib/python3/dist-packages/urllib3/connection.py", line 187, in connect
    conn = self._new_conn()
  File "/usr/lib/python3/dist-packages/urllib3/connection.py", line 171, in _new_conn
    raise NewConnectionError(
urllib3.exceptions.NewConnectionError: <urllib3.connection.HTTPConnection object at 0xffff659fdfd0>: Failed to establish a new connection: [Errno 111] Connection refused

During handling of the above exception, another exception occurred:

Traceback (most recent call last):
  File "/home/nvidia/.local/lib/python3.8/site-packages/requests/adapters.py", line 486, in send
    resp = conn.urlopen(
  File "/usr/lib/python3/dist-packages/urllib3/connectionpool.py", line 720, in urlopen
    retries = retries.increment(
  File "/usr/lib/python3/dist-packages/urllib3/util/retry.py", line 438, in increment
    raise MaxRetryError(_pool, url, error or ResponseError(cause))
urllib3.exceptions.MaxRetryError: HTTPConnectionPool(host='localhost', port=8000): Max retries exceeded with url: /measurements/ingest (Caused by NewConnectionError('<urllib3.connection.HTTPConnection object at 0xffff659fdfd0>: Failed to establish a new connection: [Errno 111] Connection refused'))

During handling of the above exception, another exception occurred:

Traceback (most recent call last):
  File "mtl_ui.py", line 554, in _handle_measure
    api_json = post_result_to_api(
  File "mtl_ui.py", line 140, in post_result_to_api
    r = requests.post(url, data=data, files=files, timeout=timeout_s)
  File "/home/nvidia/.local/lib/python3.8/site-packages/requests/api.py", line 115, in post
    return request("post", url, data=data, json=json, **kwargs)
  File "/home/nvidia/.local/lib/python3.8/site-packages/requests/api.py", line 59, in request
    return session.request(method=method, url=url, **kwargs)
  File "/home/nvidia/.local/lib/python3.8/site-packages/requests/sessions.py", line 589, in request
    resp = self.send(prep, **send_kwargs)
  File "/home/nvidia/.local/lib/python3.8/site-packages/requests/sessions.py", line 703, in send
    r = adapter.send(request, **kwargs)
  File "/home/nvidia/.local/lib/python3.8/site-packages/requests/adapters.py", line 519, in send
    raise ConnectionError(e, request=request)
requests.exceptions.ConnectionError: HTTPConnectionPool(host='localhost', port=8000): Max retries exceeded with url: /measurements/ingest (Caused by NewConnectionError('<urllib3.connection.HTTPConnection object at 0xffff659fdfd0>: Failed to establish a new connection: [Errno 111] Connection refused'))
2025-09-30 02:56:31 - MTL_MEASUREMENT - INFO - MEASURE OK run=9 W=409.13mm H=608.30mm A=99291.65mm2 Type=Asymmetrical  [S1(W=101.5,H=602.1,A=62552) | S2(W=301.2,H=114.7,A=35259)]
2025-09-30 02:56:31 - MTL_MEASUREMENT - INFO - [API] ingest ok -> {'id': 30, 'run_no': 9, 'source_filename': '', 'output_filename': 'MTL_000009.jpg', 'width_mm': 409.13, 'height_mm': 608.3, 'area_mm2': 99291.65, 'type_name': 'Asymmetrical', 'meta': {'S': [{'H_mm': 602.1, 'W_mm': 101.5, 'name': 'S1', 'A_mm2': 62552.0}, {'H_mm': 114.7, 'W_mm': 301.2, 'name': 'S2', 'A_mm2': 35259.0}]}}
2025-09-30 03:00:42 - MTL_MEASUREMENT - INFO - MEASURE OK run=10 W=409.13mm H=608.30mm A=99291.65mm2 Type=Asymmetrical  [S1(W=101.5,H=602.1,A=62552) | S2(W=301.2,H=114.7,A=35259)]
2025-09-30 03:00:42 - MTL_MEASUREMENT - INFO - [API] ingest ok -> {'id': 31, 'run_no': 10, 'source_filename': '', 'output_filename': 'MTL_000010.jpg', 'width_mm': 409.13, 'height_mm': 608.3, 'area_mm2': 99291.65, 'type_name': 'Asymmetrical', 'meta': {'S': [{'H_mm': 602.1, 'W_mm': 101.5, 'name': 'S1', 'A_mm2': 62552.0}, {'H_mm': 114.7, 'W_mm': 301.2, 'name': 'S2', 'A_mm2': 35259.0}]}}
2025-09-30 03:03:45 - MTL_MEASUREMENT - INFO - MEASURE OK run=11 W=409.13mm H=608.30mm A=99291.65mm2 Type=Asymmetrical  [S1(W=101.5,H=602.1,A=62552) | S2(W=301.2,H=114.7,A=35259)]
2025-09-30 03:03:45 - MTL_MEASUREMENT - INFO - [API] ingest ok -> {'id': 32, 'run_no': 11, 'source_filename': '', 'output_filename': 'MTL_000011.jpg', 'width_mm': 409.13, 'height_mm': 608.3, 'area_mm2': 99291.65, 'type_name': 'Asymmetrical', 'meta': {'S': [{'H_mm': 602.1, 'W_mm': 101.5, 'name': 'S1', 'A_mm2': 62552.0}, {'H_mm': 114.7, 'W_mm': 301.2, 'name': 'S2', 'A_mm2': 35259.0}]}}
2025-09-30 03:03:53 - MTL_MEASUREMENT - INFO - MEASURE OK run=12 W=409.13mm H=608.30mm A=99291.65mm2 Type=Asymmetrical  [S1(W=101.5,H=602.1,A=62552) | S2(W=301.2,H=114.7,A=35259)]
2025-09-30 03:03:53 - MTL_MEASUREMENT - INFO - [API] ingest ok -> {'id': 33, 'run_no': 12, 'source_filename': '', 'output_filename': 'MTL_000012.jpg', 'width_mm': 409.13, 'height_mm': 608.3, 'area_mm2': 99291.65, 'type_name': 'Asymmetrical', 'meta': {'S': [{'H_mm': 602.1, 'W_mm': 101.5, 'name': 'S1', 'A_mm2': 62552.0}, {'H_mm': 114.7, 'W_mm': 301.2, 'name': 'S2', 'A_mm2': 35259.0}]}}
2025-09-30 03:04:12 - MTL_MEASUREMENT - INFO - MEASURE OK run=13 W=409.13mm H=608.30mm A=99291.65mm2 Type=Asymmetrical  [S1(W=101.5,H=602.1,A=62552) | S2(W=301.2,H=114.7,A=35259)]
2025-09-30 03:04:12 - MTL_MEASUREMENT - ERROR - Send to API failed: HTTPConnectionPool(host='localhost', port=8000): Max retries exceeded with url: /measurements/ingest (Caused by NewConnectionError('<urllib3.connection.HTTPConnection object at 0xffff552922e0>: Failed to establish a new connection: [Errno 111] Connection refused'))
Traceback (most recent call last):
  File "/usr/lib/python3/dist-packages/urllib3/connection.py", line 159, in _new_conn
    conn = connection.create_connection(
  File "/usr/lib/python3/dist-packages/urllib3/util/connection.py", line 84, in create_connection
    raise err
  File "/usr/lib/python3/dist-packages/urllib3/util/connection.py", line 74, in create_connection
    sock.connect(sa)
ConnectionRefusedError: [Errno 111] Connection refused

During handling of the above exception, another exception occurred:

Traceback (most recent call last):
  File "/usr/lib/python3/dist-packages/urllib3/connectionpool.py", line 666, in urlopen
    httplib_response = self._make_request(
  File "/usr/lib/python3/dist-packages/urllib3/connectionpool.py", line 388, in _make_request
    conn.request(method, url, **httplib_request_kw)
  File "/usr/lib/python3.8/http/client.py", line 1256, in request
    self._send_request(method, url, body, headers, encode_chunked)
  File "/usr/lib/python3.8/http/client.py", line 1302, in _send_request
    self.endheaders(body, encode_chunked=encode_chunked)
  File "/usr/lib/python3.8/http/client.py", line 1251, in endheaders
    self._send_output(message_body, encode_chunked=encode_chunked)
  File "/usr/lib/python3.8/http/client.py", line 1011, in _send_output
    self.send(msg)
  File "/usr/lib/python3.8/http/client.py", line 951, in send
    self.connect()
  File "/usr/lib/python3/dist-packages/urllib3/connection.py", line 187, in connect
    conn = self._new_conn()
  File "/usr/lib/python3/dist-packages/urllib3/connection.py", line 171, in _new_conn
    raise NewConnectionError(
urllib3.exceptions.NewConnectionError: <urllib3.connection.HTTPConnection object at 0xffff552922e0>: Failed to establish a new connection: [Errno 111] Connection refused

During handling of the above exception, another exception occurred:

Traceback (most recent call last):
  File "/home/nvidia/.local/lib/python3.8/site-packages/requests/adapters.py", line 486, in send
    resp = conn.urlopen(
  File "/usr/lib/python3/dist-packages/urllib3/connectionpool.py", line 720, in urlopen
    retries = retries.increment(
  File "/usr/lib/python3/dist-packages/urllib3/util/retry.py", line 438, in increment
    raise MaxRetryError(_pool, url, error or ResponseError(cause))
urllib3.exceptions.MaxRetryError: HTTPConnectionPool(host='localhost', port=8000): Max retries exceeded with url: /measurements/ingest (Caused by NewConnectionError('<urllib3.connection.HTTPConnection object at 0xffff552922e0>: Failed to establish a new connection: [Errno 111] Connection refused'))

During handling of the above exception, another exception occurred:

Traceback (most recent call last):
  File "mtl_ui.py", line 554, in _handle_measure
    api_json = post_result_to_api(
  File "mtl_ui.py", line 140, in post_result_to_api
    r = requests.post(url, data=data, files=files, timeout=timeout_s)
  File "/home/nvidia/.local/lib/python3.8/site-packages/requests/api.py", line 115, in post
    return request("post", url, data=data, json=json, **kwargs)
  File "/home/nvidia/.local/lib/python3.8/site-packages/requests/api.py", line 59, in request
    return session.request(method=method, url=url, **kwargs)
  File "/home/nvidia/.local/lib/python3.8/site-packages/requests/sessions.py", line 589, in request
    resp = self.send(prep, **send_kwargs)
  File "/home/nvidia/.local/lib/python3.8/site-packages/requests/sessions.py", line 703, in send
    r = adapter.send(request, **kwargs)
  File "/home/nvidia/.local/lib/python3.8/site-packages/requests/adapters.py", line 519, in send
    raise ConnectionError(e, request=request)
requests.exceptions.ConnectionError: HTTPConnectionPool(host='localhost', port=8000): Max retries exceeded with url: /measurements/ingest (Caused by NewConnectionError('<urllib3.connection.HTTPConnection object at 0xffff552922e0>: Failed to establish a new connection: [Errno 111] Connection refused'))
2025-09-30 03:05:07 - MTL_MEASUREMENT - INFO - MEASURE OK run=14 W=409.13mm H=608.30mm A=99291.65mm2 Type=Asymmetrical  [S1(W=101.5,H=602.1,A=62552) | S2(W=301.2,H=114.7,A=35259)]
2025-09-30 03:05:07 - MTL_MEASUREMENT - ERROR - Send to API failed: HTTPConnectionPool(host='localhost', port=8000): Max retries exceeded with url: /measurements/ingest (Caused by NewConnectionError('<urllib3.connection.HTTPConnection object at 0xffff671e7340>: Failed to establish a new connection: [Errno 111] Connection refused'))
Traceback (most recent call last):
  File "/usr/lib/python3/dist-packages/urllib3/connection.py", line 159, in _new_conn
    conn = connection.create_connection(
  File "/usr/lib/python3/dist-packages/urllib3/util/connection.py", line 84, in create_connection
    raise err
  File "/usr/lib/python3/dist-packages/urllib3/util/connection.py", line 74, in create_connection
    sock.connect(sa)
ConnectionRefusedError: [Errno 111] Connection refused

During handling of the above exception, another exception occurred:

Traceback (most recent call last):
  File "/usr/lib/python3/dist-packages/urllib3/connectionpool.py", line 666, in urlopen
    httplib_response = self._make_request(
  File "/usr/lib/python3/dist-packages/urllib3/connectionpool.py", line 388, in _make_request
    conn.request(method, url, **httplib_request_kw)
  File "/usr/lib/python3.8/http/client.py", line 1256, in request
    self._send_request(method, url, body, headers, encode_chunked)
  File "/usr/lib/python3.8/http/client.py", line 1302, in _send_request
    self.endheaders(body, encode_chunked=encode_chunked)
  File "/usr/lib/python3.8/http/client.py", line 1251, in endheaders
    self._send_output(message_body, encode_chunked=encode_chunked)
  File "/usr/lib/python3.8/http/client.py", line 1011, in _send_output
    self.send(msg)
  File "/usr/lib/python3.8/http/client.py", line 951, in send
    self.connect()
  File "/usr/lib/python3/dist-packages/urllib3/connection.py", line 187, in connect
    conn = self._new_conn()
  File "/usr/lib/python3/dist-packages/urllib3/connection.py", line 171, in _new_conn
    raise NewConnectionError(
urllib3.exceptions.NewConnectionError: <urllib3.connection.HTTPConnection object at 0xffff671e7340>: Failed to establish a new connection: [Errno 111] Connection refused

During handling of the above exception, another exception occurred:

Traceback (most recent call last):
  File "/home/nvidia/.local/lib/python3.8/site-packages/requests/adapters.py", line 486, in send
    resp = conn.urlopen(
  File "/usr/lib/python3/dist-packages/urllib3/connectionpool.py", line 720, in urlopen
    retries = retries.increment(
  File "/usr/lib/python3/dist-packages/urllib3/util/retry.py", line 438, in increment
    raise MaxRetryError(_pool, url, error or ResponseError(cause))
urllib3.exceptions.MaxRetryError: HTTPConnectionPool(host='localhost', port=8000): Max retries exceeded with url: /measurements/ingest (Caused by NewConnectionError('<urllib3.connection.HTTPConnection object at 0xffff671e7340>: Failed to establish a new connection: [Errno 111] Connection refused'))

During handling of the above exception, another exception occurred:

Traceback (most recent call last):
  File "mtl_ui.py", line 554, in _handle_measure
    api_json = post_result_to_api(
  File "mtl_ui.py", line 140, in post_result_to_api
    r = requests.post(url, data=data, files=files, timeout=timeout_s)
  File "/home/nvidia/.local/lib/python3.8/site-packages/requests/api.py", line 115, in post
    return request("post", url, data=data, json=json, **kwargs)
  File "/home/nvidia/.local/lib/python3.8/site-packages/requests/api.py", line 59, in request
    return session.request(method=method, url=url, **kwargs)
  File "/home/nvidia/.local/lib/python3.8/site-packages/requests/sessions.py", line 589, in request
    resp = self.send(prep, **send_kwargs)
  File "/home/nvidia/.local/lib/python3.8/site-packages/requests/sessions.py", line 703, in send
    r = adapter.send(request, **kwargs)
  File "/home/nvidia/.local/lib/python3.8/site-packages/requests/adapters.py", line 519, in send
    raise ConnectionError(e, request=request)
requests.exceptions.ConnectionError: HTTPConnectionPool(host='localhost', port=8000): Max retries exceeded with url: /measurements/ingest (Caused by NewConnectionError('<urllib3.connection.HTTPConnection object at 0xffff671e7340>: Failed to establish a new connection: [Errno 111] Connection refused'))
2025-09-30 03:05:15 - MTL_MEASUREMENT - INFO - MEASURE OK run=15 W=409.13mm H=608.30mm A=99291.65mm2 Type=Asymmetrical  [S1(W=101.5,H=602.1,A=62552) | S2(W=301.2,H=114.7,A=35259)]
2025-09-30 03:05:15 - MTL_MEASUREMENT - ERROR - Send to API failed: HTTPConnectionPool(host='localhost', port=8000): Max retries exceeded with url: /measurements/ingest (Caused by NewConnectionError('<urllib3.connection.HTTPConnection object at 0xffff671e7e80>: Failed to establish a new connection: [Errno 111] Connection refused'))
Traceback (most recent call last):
  File "/usr/lib/python3/dist-packages/urllib3/connection.py", line 159, in _new_conn
    conn = connection.create_connection(
  File "/usr/lib/python3/dist-packages/urllib3/util/connection.py", line 84, in create_connection
    raise err
  File "/usr/lib/python3/dist-packages/urllib3/util/connection.py", line 74, in create_connection
    sock.connect(sa)
ConnectionRefusedError: [Errno 111] Connection refused

During handling of the above exception, another exception occurred:

Traceback (most recent call last):
  File "/usr/lib/python3/dist-packages/urllib3/connectionpool.py", line 666, in urlopen
    httplib_response = self._make_request(
  File "/usr/lib/python3/dist-packages/urllib3/connectionpool.py", line 388, in _make_request
    conn.request(method, url, **httplib_request_kw)
  File "/usr/lib/python3.8/http/client.py", line 1256, in request
    self._send_request(method, url, body, headers, encode_chunked)
  File "/usr/lib/python3.8/http/client.py", line 1302, in _send_request
    self.endheaders(body, encode_chunked=encode_chunked)
  File "/usr/lib/python3.8/http/client.py", line 1251, in endheaders
    self._send_output(message_body, encode_chunked=encode_chunked)
  File "/usr/lib/python3.8/http/client.py", line 1011, in _send_output
    self.send(msg)
  File "/usr/lib/python3.8/http/client.py", line 951, in send
    self.connect()
  File "/usr/lib/python3/dist-packages/urllib3/connection.py", line 187, in connect
    conn = self._new_conn()
  File "/usr/lib/python3/dist-packages/urllib3/connection.py", line 171, in _new_conn
    raise NewConnectionError(
urllib3.exceptions.NewConnectionError: <urllib3.connection.HTTPConnection object at 0xffff671e7e80>: Failed to establish a new connection: [Errno 111] Connection refused

During handling of the above exception, another exception occurred:

Traceback (most recent call last):
  File "/home/nvidia/.local/lib/python3.8/site-packages/requests/adapters.py", line 486, in send
    resp = conn.urlopen(
  File "/usr/lib/python3/dist-packages/urllib3/connectionpool.py", line 720, in urlopen
    retries = retries.increment(
  File "/usr/lib/python3/dist-packages/urllib3/util/retry.py", line 438, in increment
    raise MaxRetryError(_pool, url, error or ResponseError(cause))
urllib3.exceptions.MaxRetryError: HTTPConnectionPool(host='localhost', port=8000): Max retries exceeded with url: /measurements/ingest (Caused by NewConnectionError('<urllib3.connection.HTTPConnection object at 0xffff671e7e80>: Failed to establish a new connection: [Errno 111] Connection refused'))

During handling of the above exception, another exception occurred:

Traceback (most recent call last):
  File "mtl_ui.py", line 554, in _handle_measure
    api_json = post_result_to_api(
  File "mtl_ui.py", line 140, in post_result_to_api
    r = requests.post(url, data=data, files=files, timeout=timeout_s)
  File "/home/nvidia/.local/lib/python3.8/site-packages/requests/api.py", line 115, in post
    return request("post", url, data=data, json=json, **kwargs)
  File "/home/nvidia/.local/lib/python3.8/site-packages/requests/api.py", line 59, in request
    return session.request(method=method, url=url, **kwargs)
  File "/home/nvidia/.local/lib/python3.8/site-packages/requests/sessions.py", line 589, in request
    resp = self.send(prep, **send_kwargs)
  File "/home/nvidia/.local/lib/python3.8/site-packages/requests/sessions.py", line 703, in send
    r = adapter.send(request, **kwargs)
  File "/home/nvidia/.local/lib/python3.8/site-packages/requests/adapters.py", line 519, in send
    raise ConnectionError(e, request=request)
requests.exceptions.ConnectionError: HTTPConnectionPool(host='localhost', port=8000): Max retries exceeded with url: /measurements/ingest (Caused by NewConnectionError('<urllib3.connection.HTTPConnection object at 0xffff671e7e80>: Failed to establish a new connection: [Errno 111] Connection refused'))
2025-09-30 03:05:32 - MTL_MEASUREMENT - INFO - MEASURE OK run=16 W=409.13mm H=608.30mm A=99291.65mm2 Type=Asymmetrical  [S1(W=101.5,H=602.1,A=62552) | S2(W=301.2,H=114.7,A=35259)]
2025-09-30 03:05:32 - MTL_MEASUREMENT - INFO - [API] ingest ok -> {'id': 34, 'run_no': 16, 'source_filename': '', 'output_filename': 'MTL_000016.jpg', 'width_mm': 409.13, 'height_mm': 608.3, 'area_mm2': 99291.65, 'type_name': 'Asymmetrical', 'meta': {'S': [{'H_mm': 602.1, 'W_mm': 101.5, 'name': 'S1', 'A_mm2': 62552.0}, {'H_mm': 114.7, 'W_mm': 301.2, 'name': 'S2', 'A_mm2': 35259.0}]}}
2025-09-30 03:06:03 - MTL_MEASUREMENT - WARNING - MEASURE NO_OBJECT
2025-09-30 03:10:11 - MTL_MEASUREMENT - INFO - MEASURE OK run=17 W=409.13mm H=608.30mm A=99291.65mm2 Type=Asymmetrical  [S1(W=101.5,H=602.1,A=62552) | S2(W=301.2,H=114.7,A=35259)]
2025-09-30 03:10:11 - MTL_MEASUREMENT - INFO - [API] ingest ok -> {'id': 35, 'run_no': 17, 'source_filename': '', 'output_filename': 'MTL_000017.jpg', 'width_mm': 409.13, 'height_mm': 608.3, 'area_mm2': 99291.65, 'type_name': 'Asymmetrical', 'meta': {'S': [{'H_mm': 602.1, 'W_mm': 101.5, 'name': 'S1', 'A_mm2': 62552.0}, {'H_mm': 114.7, 'W_mm': 301.2, 'name': 'S2', 'A_mm2': 35259.0}]}}
2025-09-30 03:10:25 - MTL_MEASUREMENT - INFO - MEASURE OK run=18 W=409.13mm H=608.30mm A=99291.65mm2 Type=Asymmetrical  [S1(W=101.5,H=602.1,A=62552) | S2(W=301.2,H=114.7,A=35259)]
2025-09-30 03:10:25 - MTL_MEASUREMENT - ERROR - Send to API failed: HTTPConnectionPool(host='localhost', port=8000): Max retries exceeded with url: /measurements/ingest (Caused by NewConnectionError('<urllib3.connection.HTTPConnection object at 0xffff929a7550>: Failed to establish a new connection: [Errno 111] Connection refused'))
Traceback (most recent call last):
  File "/usr/lib/python3/dist-packages/urllib3/connection.py", line 159, in _new_conn
    conn = connection.create_connection(
  File "/usr/lib/python3/dist-packages/urllib3/util/connection.py", line 84, in create_connection
    raise err
  File "/usr/lib/python3/dist-packages/urllib3/util/connection.py", line 74, in create_connection
    sock.connect(sa)
ConnectionRefusedError: [Errno 111] Connection refused

During handling of the above exception, another exception occurred:

Traceback (most recent call last):
  File "/usr/lib/python3/dist-packages/urllib3/connectionpool.py", line 666, in urlopen
    httplib_response = self._make_request(
  File "/usr/lib/python3/dist-packages/urllib3/connectionpool.py", line 388, in _make_request
    conn.request(method, url, **httplib_request_kw)
  File "/usr/lib/python3.8/http/client.py", line 1256, in request
    self._send_request(method, url, body, headers, encode_chunked)
  File "/usr/lib/python3.8/http/client.py", line 1302, in _send_request
    self.endheaders(body, encode_chunked=encode_chunked)
  File "/usr/lib/python3.8/http/client.py", line 1251, in endheaders
    self._send_output(message_body, encode_chunked=encode_chunked)
  File "/usr/lib/python3.8/http/client.py", line 1011, in _send_output
    self.send(msg)
  File "/usr/lib/python3.8/http/client.py", line 951, in send
    self.connect()
  File "/usr/lib/python3/dist-packages/urllib3/connection.py", line 187, in connect
    conn = self._new_conn()
  File "/usr/lib/python3/dist-packages/urllib3/connection.py", line 171, in _new_conn
    raise NewConnectionError(
urllib3.exceptions.NewConnectionError: <urllib3.connection.HTTPConnection object at 0xffff929a7550>: Failed to establish a new connection: [Errno 111] Connection refused

During handling of the above exception, another exception occurred:

Traceback (most recent call last):
  File "/home/nvidia/.local/lib/python3.8/site-packages/requests/adapters.py", line 486, in send
    resp = conn.urlopen(
  File "/usr/lib/python3/dist-packages/urllib3/connectionpool.py", line 720, in urlopen
    retries = retries.increment(
  File "/usr/lib/python3/dist-packages/urllib3/util/retry.py", line 438, in increment
    raise MaxRetryError(_pool, url, error or ResponseError(cause))
urllib3.exceptions.MaxRetryError: HTTPConnectionPool(host='localhost', port=8000): Max retries exceeded with url: /measurements/ingest (Caused by NewConnectionError('<urllib3.connection.HTTPConnection object at 0xffff929a7550>: Failed to establish a new connection: [Errno 111] Connection refused'))

During handling of the above exception, another exception occurred:

Traceback (most recent call last):
  File "mtl_ui.py", line 554, in _handle_measure
    api_json = post_result_to_api(
  File "mtl_ui.py", line 140, in post_result_to_api
    r = requests.post(url, data=data, files=files, timeout=timeout_s)
  File "/home/nvidia/.local/lib/python3.8/site-packages/requests/api.py", line 115, in post
    return request("post", url, data=data, json=json, **kwargs)
  File "/home/nvidia/.local/lib/python3.8/site-packages/requests/api.py", line 59, in request
    return session.request(method=method, url=url, **kwargs)
  File "/home/nvidia/.local/lib/python3.8/site-packages/requests/sessions.py", line 589, in request
    resp = self.send(prep, **send_kwargs)
  File "/home/nvidia/.local/lib/python3.8/site-packages/requests/sessions.py", line 703, in send
    r = adapter.send(request, **kwargs)
  File "/home/nvidia/.local/lib/python3.8/site-packages/requests/adapters.py", line 519, in send
    raise ConnectionError(e, request=request)
requests.exceptions.ConnectionError: HTTPConnectionPool(host='localhost', port=8000): Max retries exceeded with url: /measurements/ingest (Caused by NewConnectionError('<urllib3.connection.HTTPConnection object at 0xffff929a7550>: Failed to establish a new connection: [Errno 111] Connection refused'))
2025-09-30 03:10:45 - MTL_MEASUREMENT - WARNING - MEASURE NO_OBJECT
2025-09-30 03:10:49 - MTL_MEASUREMENT - WARNING - MEASURE NO_OBJECT
2025-09-30 03:32:47 - MTL_MEASUREMENT - INFO - MEASURE OK run=1 W=409.13mm H=608.30mm A=99291.65mm2 Type=Asymmetrical  [S1(W=101.5,H=602.1,A=62552) | S2(W=301.2,H=114.7,A=35259)]
2025-09-30 03:32:47 - MTL_MEASUREMENT - ERROR - Send to API failed: HTTPConnectionPool(host='localhost', port=8000): Max retries exceeded with url: /measurements/ingest (Caused by NewConnectionError('<urllib3.connection.HTTPConnection object at 0xffff64982fa0>: Failed to establish a new connection: [Errno 111] Connection refused'))
Traceback (most recent call last):
  File "/usr/lib/python3/dist-packages/urllib3/connection.py", line 159, in _new_conn
    conn = connection.create_connection(
  File "/usr/lib/python3/dist-packages/urllib3/util/connection.py", line 84, in create_connection
    raise err
  File "/usr/lib/python3/dist-packages/urllib3/util/connection.py", line 74, in create_connection
    sock.connect(sa)
ConnectionRefusedError: [Errno 111] Connection refused

During handling of the above exception, another exception occurred:

Traceback (most recent call last):
  File "/usr/lib/python3/dist-packages/urllib3/connectionpool.py", line 666, in urlopen
    httplib_response = self._make_request(
  File "/usr/lib/python3/dist-packages/urllib3/connectionpool.py", line 388, in _make_request
    conn.request(method, url, **httplib_request_kw)
  File "/usr/lib/python3.8/http/client.py", line 1256, in request
    self._send_request(method, url, body, headers, encode_chunked)
  File "/usr/lib/python3.8/http/client.py", line 1302, in _send_request
    self.endheaders(body, encode_chunked=encode_chunked)
  File "/usr/lib/python3.8/http/client.py", line 1251, in endheaders
    self._send_output(message_body, encode_chunked=encode_chunked)
  File "/usr/lib/python3.8/http/client.py", line 1011, in _send_output
    self.send(msg)
  File "/usr/lib/python3.8/http/client.py", line 951, in send
    self.connect()
  File "/usr/lib/python3/dist-packages/urllib3/connection.py", line 187, in connect
    conn = self._new_conn()
  File "/usr/lib/python3/dist-packages/urllib3/connection.py", line 171, in _new_conn
    raise NewConnectionError(
urllib3.exceptions.NewConnectionError: <urllib3.connection.HTTPConnection object at 0xffff64982fa0>: Failed to establish a new connection: [Errno 111] Connection refused

During handling of the above exception, another exception occurred:

Traceback (most recent call last):
  File "/home/nvidia/.local/lib/python3.8/site-packages/requests/adapters.py", line 486, in send
    resp = conn.urlopen(
  File "/usr/lib/python3/dist-packages/urllib3/connectionpool.py", line 720, in urlopen
    retries = retries.increment(
  File "/usr/lib/python3/dist-packages/urllib3/util/retry.py", line 438, in increment
    raise MaxRetryError(_pool, url, error or ResponseError(cause))
urllib3.exceptions.MaxRetryError: HTTPConnectionPool(host='localhost', port=8000): Max retries exceeded with url: /measurements/ingest (Caused by NewConnectionError('<urllib3.connection.HTTPConnection object at 0xffff64982fa0>: Failed to establish a new connection: [Errno 111] Connection refused'))

During handling of the above exception, another exception occurred:

Traceback (most recent call last):
  File "mtl_ui.py", line 554, in _handle_measure
    api_json = post_result_to_api(
  File "mtl_ui.py", line 140, in post_result_to_api
    r = requests.post(url, data=data, files=files, timeout=timeout_s)
  File "/home/nvidia/.local/lib/python3.8/site-packages/requests/api.py", line 115, in post
    return request("post", url, data=data, json=json, **kwargs)
  File "/home/nvidia/.local/lib/python3.8/site-packages/requests/api.py", line 59, in request
    return session.request(method=method, url=url, **kwargs)
  File "/home/nvidia/.local/lib/python3.8/site-packages/requests/sessions.py", line 589, in request
    resp = self.send(prep, **send_kwargs)
  File "/home/nvidia/.local/lib/python3.8/site-packages/requests/sessions.py", line 703, in send
    r = adapter.send(request, **kwargs)
  File "/home/nvidia/.local/lib/python3.8/site-packages/requests/adapters.py", line 519, in send
    raise ConnectionError(e, request=request)
requests.exceptions.ConnectionError: HTTPConnectionPool(host='localhost', port=8000): Max retries exceeded with url: /measurements/ingest (Caused by NewConnectionError('<urllib3.connection.HTTPConnection object at 0xffff64982fa0>: Failed to establish a new connection: [Errno 111] Connection refused'))
